Workbook

Sheet Okuma Kılavuzu
A1: Enerji Yatırım Destekleri Veri Envanteri 2026
A2: Türkiye'de enerji yatırımları için kamu destekleri, uygunluk kuralları ve il katmanı · Son kontrol: 26.09.2026
A4: Bölüm | B4: Açıklama
A5: Amaç | B5: Belirli bir enerji yatırımı için hangi kamu desteğine, hangi şartla, hangi ilde ve ne kadar erişilebileceğini gösteren karar motoruna veri sağlamak. Her satır kaynak, madde ve etiket taşır.
A6: Kapsam | B6: 9903 sayılı Karar (THP, YKH, Stratejik, Öncelikli, Hedef, bölgesel), Yeşil Dönüşüm Programı, VAP, EPS, EKA, KOSGEB, TÜBİTAK 1832, HIT-30, YEKDEM, lisanssız üretim, YEKA 2026, kalkınma ajansları.
A7: Destek sınıfları | B7: Yatırım desteği (hibe, vergi, faiz, KDV, gümrük, SGK) · Performans desteği (EKA) · Gelir/piyasa desteği (YEKDEM, lisanssız ihtiyaç fazlası) · Kapasite tahsisi (YEKA) · Ar-Ge desteği (1832). Sınıflar karıştırılmamalı; YEKDEM bir yatırım hibesi değildir.
A8: Yöntem | B8: Resmî Gazete PDF'leri (taranmış ekler dahil), Bakanlık duyuruları ve usul-esas belgeleri doğrudan okundu. Resmî Gazete'ye erişilemeyen yerlerde Lexpera konsolide metinleri kullanıldı. İkincil kaynaktan gelen her bilgi 'Teyit edilecek' etiketlidir.
A9: Yeniden değerleme oranı | B9: Parasal eşikler sayfasındaki sarı hücre (%25,49) değiştirildiğinde hesaplanan 2026 tutarları kendiliğinden güncellenir. 2027 için yeni oran girilip ilan edilen tutarlarla karşılaştırılabilir.
A10: Sayfalar | B10: Programlar · Destek Unsurları · Uygunluk Kuralları · Yatırım Türü Matrisi · Matris Gerekçeleri · İller · Bölgesel Kurallar · YKH Konuları · Kümülasyon · Parasal Eşikler 2026 · YEKDEM Fiyatları · Gümrük (EK-4) · Takvim ve Çağrılar · Kaynaklar · Teyit Listesi
A11: Uyarı | B11: Ön değerlendirme verisidir. Destek kararı ilgili kurumun incelemesiyle verilir; başvuru öncesinde güncel mevzuat ve ilanlar kontrol edilmelidir.
A13: Etiket | B13: Anlamı
A14: Mevzuat | B14: Resmî Gazete'de yayımlı metin ya da ona dayanan usul ve esaslar; madde numarası yanında.
A15: Duyuru | B15: Bakanlık/kurumun resmî duyurusu veya program sayfası.
A16: Hesaplanan | B16: Bu envanterde formülle hesaplanır (ör. yeniden değerleme).
... A19: Yorum | B19: Mevzuatta açık hüküm yok; maddelerden çıkarılan değerlendirme.
A21: Öne çıkan bulgular
A22: KOSGEB KOBİ Enerji Verimliliği | B22: KOSGEB sitesinde 'Yürürlükten Kaldırılan Destekler' altında; güncel program listesinde yok.
A23: İl farkının sınırı | B23: 9903'te vergi indirimi ve faiz oranları programa bağlı; il değişince asgari tutar, SGK süresi, Hedef faizi (4-6. bölge), İstanbul istisnası ve geçici m.3-4 değişir.
A24: Geçici m.3-4 (31.12.2026) | B24: Deprem ilçeleri ile Cazibe Merkezleri illerindeki OSB imalat yatırımları 6. bölge desteklerinden yararlanır; müracaat için son tarih 31.12.2026.
A25: GES'te EK-3 şartı | B25: 240 kW altı (çatı dahil) ve modernizasyon niteliğindeki GES yatırımları 9903'te desteklenmez; öz tüketimde teşvik sözleşme gücüyle sınırlı.
A26: Li-ion batarya gümrüğü | B26: 8507.60 lityum iyon aküler EK-4'te: teşvik belgesi olsa da gümrük muafiyeti yok. İnverter, trafo, PV modül ve ısı pompası listede değil.
A27: Çimento ve temel çelik | B27: EK-3 dışı veya dar; bu sektörlerde enerji verimliliği için 9903'e yol Yeşil Dönüşüm Programı.
A28: Ekosistem geliştirme planı | B28: KOBİ olmayan ve vergi indirimi alan yatırımcı, SYT'nin en az %2'si tutarında plan uygulamakla yükümlü (9903 m.5/9).
A29: LÜY m.37/10 | B29: Dağıtım ve görevli tedarik şirketlerinin ortakları ve kontrolündeki şirketler, kendi dağıtım bölgelerinde lisanssız RES/GES başvurusu yapamaz; ESCO modelinde başvuru sahibi müşteri olmalı.
A30: Lisanssız 10 yıl sonrası | B30: 11415 sayılı CBK: ihtiyaç fazlası, aynı tip lisanslı tesisin YEKDEM fiyatının %90'ından alınır; PTF'yi aşamaz.
A31: Kümülasyon | B31: Aynı ekipman için VAP, EPS, 9903 ve KOSGEB'den yalnız biri. VAP ile EKA tamamlayıcı.

Sheet Programlar
A1: Programlar
A2: Her program bir satır. Destek sınıfı sütunu, yatırım desteğini gelir/piyasa desteğinden ayırır.
A4: ID | B4: Program | C4: Kurum | D4: Destek sınıfı | E4: Niteliği | F4: 2026 durumu | G4: Başvuru kanalı | H4: Başvuru dönemi | I4: Hedef yatırımcı | J4: Dayanak | K4: Etiket | L4: Kaynak | M4: Not | N4: Son kontrol
A5: P01 | B5: 9903 · Teknoloji Hamlesi Programı (THP) | C5: Sanayi ve Teknoloji Bakanlığı (SAVGM) | D5: Yatırım desteği | E5: Yatırım desteği | F5: Açık | G5: E-TUYS + THP Değerlendirme Komitesi | H5: 31.12.2030'a kadar | I5: Öncelikli ürün listesindeki yüksek teknoloji yatırımcıları | J5: 9903 m.4/2, m.6 | K5: Mevzuat | L5: K02 | M5: Proje bazlı; komite kararı. | N5: 26.09.2026
A6: P02 | B6: 9903 · Yerel Kalkınma Hamlesi Programı (YKH) | C6: Sanayi ve Teknoloji Bakanlığı (Kalkınma Ajansları GM) | D6: Yatırım desteği | E6: Yatırım desteği | F6: 2026 dönemi kapandı | G6: Kalkınma ajansı + YKH Değerlendirme Komitesi | H6: 2026: 02.03-15.05.2026 | I6: İlin 4 yerel yatırım konusunda yatırım yapanlar | J6: 9903 m.7; Yerel Yatırım Konuları Listesi Tebliği | K6: Mevzuat | L6: K02, K05, K31 | M6: Liste her yıl ocak ayında güncellenebilir. | N6: 26.09.2026
A7: P03 | B7: 9903 · Stratejik Hamle Programı | C7: Sanayi ve Teknoloji Bakanlığı | D7: Yatırım desteği | E7: Yatırım desteği | F7: Açık | G7: E-TUYS + Stratejik Hamle Değerlendirme Komitesi | H7: 31.12.2030'a kadar | I7: Büyük ölçekli, ithalatı azaltan imalat; ≥ 62,7 mn TL yeşil/dijital dönüşüm | J7: 9903 m.8 | K7: Mevzuat | L7: K02 | N7: 26.09.2026
A8: P04 | B8: 9903 · Öncelikli Yatırımlar Teşvik Sistemi | C8: Sanayi ve Teknoloji Bakanlığı | D8: Yatırım desteği | E8: Yatırım desteği | F8: Açık | G8: E-TUYS | H8: 31.12.2030'a kadar | I8: m.9/1'de sayılan konular (öz tüketim GES/RES, yeşil/dijital dönüşüm, 6. bölge vb.) | J8: 9903 m.9 | K8: Mevzuat | L8: K02 | N8: 26.09.2026
A9: P05 | B9: 9903 · Hedef Yatırımlar Teşvik Sistemi (EK-3) | C9: Sanayi ve Teknoloji Bakanlığı | D9: Yatırım desteği | E9: Yatırım desteği | F9: Açık | G9: E-TUYS | H9: 31.12.2030'a kadar | I9: EK-3'teki konular ve şartlar | J9: 9903 m.10, EK-3 | K9: Mevzuat | L9: K01, K02 | M9: Elektrik üretimi, dağıtım, depolama ve gaz dağıtımında yalnız KDV ve gümrük kalır. | N9: 26.09.2026
A10: P06 | B10: 9903 · Bölgesel teşvikler (SGK desteği) | C10: Sanayi ve Teknoloji Bakanlığı / SGK | D10: Yatırım desteği | E10: Yatırım desteği (istihdam) | F10: Açık | G10: Teşvik belgesiyle otomatik | H10: 31.12.2030'a kadar | I10: TYKH ve sektörel sistemde belge alan tüm yatırımlar | J10: 9903 m.4/4, m.18, m.19, m.22 | K10: Mevzuat | L10: K02 | N10: 26.09.2026
A11: P07 | B11: Yeşil Dönüşüm Programı (9903 m.12) → Öncelikli / Stratejik | C11: Sanayi ve Teknoloji Bakanlığı (SAVGM) | D11: Yatırım desteği | E11: Yatırım desteği | F11: Açık (çağrıya göre) | G11: Program portalı → E-TUYS | H11: Çağrı bazında | I11: İmalat sanayiinde sermaye şirketleri | J11: 9903 m.9/1-a, m.8/8, m.12; YDDP Tebliği | K11: Mevzuat | L11: K02, K06 | M11: EK-3 şartı aranmaz (m.5/1). | N11: 26.09.2026
A12: P08 | B12: Verimlilik Artırıcı Proje (VAP) Desteği | C12: Enerji ve Tabii Kaynaklar Bakanlığı | D12: Yatırım desteği | E12: Yatırım desteği (hibe) | F12: Açık | G12: evdes.enerji.gov.tr | H12: İlan edilen dönem | I12: Kamu dışı tüzel kişiler | J12: EVY m.16/2; VAP UE | K12: Mevzuat | L12: K09, K10, K11 | M12: 2027'den itibaren etüt dışı projede oran %25. | N12: 26.09.2026
A13: P09 | B13: Enerji Performans Sözleşmesi (EPS) Desteği | C13: Enerji ve Tabii Kaynaklar Bakanlığı | D13: Yatırım desteği | E13: Yatırım desteği (hibe, ESCO üzerinden) | F13: Açık | G13: evdes.enerji.gov.tr (başvuruyu ESCO yapar) | H13: İlan edilen dönem | I13: Enerji yöneticisi görevlendirmekle yükümlü işletme + ESCO | J13: 5627 m.8/1-a; EVY m.16; EPS UE | K13: Mevzuat | L13: K16, K17 | N13: 26.09.2026
A14: P10 | B14: Enerji ve Karbon Azaltım (EKA) Desteği | C14: Enerji ve Tabii Kaynaklar Bakanlığı | D14: Performans desteği | E14: Performans desteği (hibe) | F14: Açık · 30.09.2026'da kapanıyor | G14: evdes.enerji.gov.tr | H14: 01.07-30.09.2026 | I14: İmalat; otel, AVM, hastane, ofis binaları | J14: EVY m.16/3; EKA UE | K14: Mevzuat | L14: K14, K15 | M14: Her sektörde ilk 10 izlemeye alınır. | N14: 26.09.2026
A15: P11 | B15: KOSGEB Yeşil Sanayi Destek Programı | C15: KOSGEB (Dünya Bankası TYSP Bileşen 1) | D15: Yatırım desteği | E15: Yatırım desteği (geri ödemeli) | F15: Çağrı durumu teyit edilecek | G15: KOSGEB e-Hizmetler | H15: Çağrı bazında (2023-01, 2023-02) | I15: Sanayi KOBİ'leri | J15: KOSGEB YSDP Yönergesi | K15: Duyuru | L15: K26 | N15: 26.09.2026
A16: P12 | B16: KOSGEB KOBİ Enerji Verimliliği Destek Programı | C16: KOSGEB | D16: Yatırım desteği | E16: Yatırım desteği | F16: Yürürlükten kaldırıldı | G16: — | H16: — | I16: — | J16: — | K16: Duyuru | L16: K27, K28 | M16: KOSGEB sitesinde 'Yürürlükten Kaldırılan Destekler' altında; güncel listede yok. | N16: 26.09.2026
A17: P13 | B17: TÜBİTAK 1832 Sanayide Yeşil Dönüşüm (Ar-Ge) | C17: TÜBİTAK TEYDEB (Dünya Bankası TYSP) | D17: Ar-Ge desteği | E17: Ar-Ge desteği (hibe + faizsiz geri ödemeli) | F17: Açık · 12.10.2026'da kapanıyor | G17: PRODİS (eteydeb.tubitak.gov.tr) | H17: 2026-2 çağrısı: kapanış 12.10.2026 | I17: KOBİ ve büyük ölçekli kuruluşlar | J17: 1801/1832 program esasları | K17: Duyuru | L17: K29 | M17: Yatırım değil Ar-Ge (THS 3-9). | N17: 26.09.2026
A18: P14 | B18: HIT-30 Yüksek Teknoloji Yatırım Programı | C18: Sanayi ve Teknoloji Bakanlığı | D18: Yatırım desteği | E18: Proje bazlı yatırım desteği | F18: Açık (HIT-Battery, HIT-Wind); HIT-Solar kapandı | G18: hit30@sanayi.gov.tr / çağrı | H18: Çağrı olmadan da başvurulabilir | I18: Küresel ölçekli yüksek teknoloji yatırımcıları | J18: Proje bazlı teşvik; HIT-30 program belgeleri | K18: Duyuru | L18: K25 | M18: Yeşil enerji: yeşil hidrojen, elektrolizör, rüzgâr, güneş hücresi/wafer/ingot, depolama bataryası, batarya bileşenleri, kritik mineraller. | N18: 26.09.2026
A19: P15 | B19: YEKDEM (Yenilenebilir Enerji Kaynakları Destekleme Mekanizması) | C19: ETKB / EPDK / EPİAŞ | D19: Gelir / piyasa desteği | E19: Gelir / piyasa desteği | F19: Açık (31.12.2030'a kadar işletmeye girenler) | G19: YEK Belgesi (EPDK) + YEKDEM listesi | H19: Yıllık kayıt | I19: Lisanslı YEK üreticileri | J19: 5346 m.6, m.6/B; 7189 sayılı CBK | K19: Mevzuat | L19: K19 | M19: Yatırım hibesi değildir; üretilen elektriğin fiyatını destekler. | N19: 26.09.2026
A20: P16 | B20: Lisanssız üretim (öz tüketim, mahsuplaşma, ihtiyaç fazlası) | C20: EPDK / dağıtım şirketleri | D20: Gelir / piyasa düzenlemesi | E20: Gelir / piyasa düzenlemesi | F20: Açık | G20: İlgili dağıtım şirketi | H20: Sürekli | I20: Tüketim tesisi sahipleri | J20: LÜY; 11415 sayılı CBK | K20: Mevzuat | L20: K18, K20 | N20: 26.09.2026
A21: P17 | B21: YEKA 2026 (GES-2026, RES-2026 yarışmaları) | C21: Enerji ve Tabii Kaynaklar Bakanlığı | D21: Kapasite tahsisi | E21: Kapasite tahsisi + alım garantisi | F21: Açık · başvuru 13.10.2026 | G21: Yarışma başvurusu (ETKB) | H21: Başvuru: 13.10.2026 | I21: Tüzel kişiler (yerli ve yabancı) | J21: YEKA Yönetmeliği; GES/RES-2026 şartnameleri | K21: Mevzuat | L21: K21, K22, K23 | M21: 21 yarışma: 14 GES (900 MWe), 7 RES (1.500 MWe). | N21: 26.09.2026
A22: P18 | B22: Kalkınma ajansı mali destek programları | C22: 26 kalkınma ajansı | D22: Yatırım desteği | E22: Hibe / faizsiz kredi (programa göre) | F22: Ajans bazında | G22: Ajans başvuru sistemi | H22: Ajans bazında | I22: Programa göre | J22: 5449 sayılı Kanun | K22: Yorum | L22: K30 | M22: Çağrılar ajanstan ajansa değişir; bu envanterde ayrıntılandırılmadı. | N22: 26.09.2026

Sheet Destek Unsurları
A1: Destek unsurları
A2: Program adı Programlar sayfasından formülle gelir.
A4: Program ID | B4: Program | C4: Destek unsuru | D4: Oran / ölçü | E4: 2026 üst sınır | F4: Süre | G4: Hesap | H4: Dayanak | I4: Etiket | J4: Kaynak
A5: P01 | B5: =IFERROR(INDEX(Programlar!$B$5:$B$22,MATCH(A5,Programlar!$A$5:$A$22,0)),"") -> 9903 · Teknoloji Hamlesi Programı (THP) | C5: Gümrük vergisi muafiyeti | D5: Makine-teçhizat (EK-4 hariç) | E5: — | F5: Belge süresi | G5: — | H5: 9903 m.13 | I5: Mevzuat | J5: K02
A6: P01 | B6: =IFERROR(INDEX(Programlar!$B$5:$B$22,MATCH(A6,Programlar!$A$5:$A$22,0)),"") -> 9903 · Teknoloji Hamlesi Programı (THP) | C6: KDV istisnası | D6: Makine-teçhizat, yazılım | E6: — | F6: Belge süresi | G6: — | H6: 9903 m.14 | I6: Mevzuat | J6: K02
A7: P01 | B7: =IFERROR(INDEX(Programlar!$B$5:$B$22,MATCH(A7,Programlar!$A$5:$A$22,0)),"") -> 9903 · Teknoloji Hamlesi Programı (THP) | C7: Vergi indirimi | D7: Katkı %50, indirim %60 | E7: Katkı tutarı | F7: Katkıya ulaşıncaya kadar | G7: Katkı = SYT × %50 | H7: 9903 m.20/1-a | I7: Mevzuat | J7: K02
A8: P01 | B8: =IFERROR(INDEX(Programlar!$B$5:$B$22,MATCH(A8,Programlar!$A$5:$A$22,0)),"") -> 9903 · Teknoloji Hamlesi Programı (THP) | C8: Faiz/kâr payı desteği | D8: Repo × %40, ≤ 20 puan; kredinin SYT %70'ine kadarı | E8: SYT %20 ve 301 mn TL | F8: ≤ 5 yıl | G8: min(Kredi, %70 SYT) × puan | H8: 9903 m.15/1-a, m.15/3-a | I8: Mevzuat + Teyit edilecek | J8: K02, K04
A9: P01 | B9: =IFERROR(INDEX(Programlar!$B$5:$B$22,MATCH(A9,Programlar!$A$5:$A$22,0)),"") -> 9903 · Teknoloji Hamlesi Programı (THP) | C9: Makine desteği | D9: Birim ≥ 2,5 mn TL makinelerin %25'i | E9: SYT %15 ve 301 mn TL | F9: Yatırım süresi | G9: %25 × uygun makine | H9: 9903 m.16 | I9: Mevzuat + Teyit edilecek | J9: K02, K04
A10: P01 | B10: =IFERROR(INDEX(Programlar!$B$5:$B$22,MATCH(A10,Programlar!$A$5:$A$22,0)),"") -> 9903 · Teknoloji Hamlesi Programı (THP) | C10: SGK işveren hissesi | D10: Asgari ücret kısmı; 6. bölge tamamı, diğer %50 | E10: — | F10: 8 yıl (6. bölge 12) | G10: — | H10: 9903 m.18/3 | I10: Mevzuat | J10: K02
A11: P01 | B11: =IFERROR(INDEX(Programlar!$B$5:$B$22,MATCH(A11,Programlar!$A$5:$A$22,0)),"") -> 9903 · Teknoloji Hamlesi Programı (THP) | C11: Yatırım yeri tahsisi | D11: — | E11: — | F11: — | G11: — | H11: 9903 m.21/2 | I11: Mevzuat | J11: K02
A12: P02 | B12: =IFERROR(INDEX(Programlar!$B$5:$B$22,MATCH(A12,Programlar!$A$5:$A$22,0)),"") -> 9903 · Yerel Kalkınma Hamlesi Programı (YKH) | C12: Destek seti THP ile aynı | D12: Vergi %50; faiz %40 (≤ 20 puan); makine %25 | E12: SYT %20 / %15 ve 301 mn TL | F12: ≤ 5 yıl | G12: — | H12: 9903 m.15/1-a, m.16, m.20/1-a | I12: Mevzuat + Teyit edilecek | J12: K02, K04
A13: P02 | B13: =IFERROR(INDEX(Programlar!$B$5:$B$22,MATCH(A13,Programlar!$A$5:$A$22,0)),"") -> 9903 · Yerel Kalkınma Hamlesi Programı (YKH) | C13: Ekosistem geliştirme planı (yükümlülük) | D13: Tamamlama vizesine kadar SYT'nin ≥ %2'si | E13: — | F13: — | G13: — | H13: 9903 m.5/9 | I13: Mevzuat | J13: K02
A14: P03 | B14: =IFERROR(INDEX(Programlar!$B$5:$B$22,MATCH(A14,Programlar!$A$5:$A$22,0)),"") -> 9903 · Stratejik Hamle Programı | C14: Vergi indirimi | D14: Katkı %40, indirim %60 | E14: Katkı tutarı | F14: — | G14: Katkı = SYT × %40 | H14: 9903 m.20/1-b | I14: Mevzuat | J14: K02
A15: P03 | B15: =IFERROR(INDEX(Programlar!$B$5:$B$22,MATCH(A15,Programlar!$A$5:$A$22,0)),"") -> 9903 · Stratejik Hamle Programı | C15: Faiz/kâr payı desteği | D15: Repo × %30, ≤ 15 puan | E15: SYT %15 ve 226 mn TL | F15: ≤ 5 yıl | G15: — | H15: 9903 m.15/1-b, m.15/3-b | I15: Mevzuat + Teyit edilecek | J15: K02, K04
A16: P03 | B16: =IFERROR(INDEX(Programlar!$B$5:$B$22,MATCH(A16,Programlar!$A$5:$A$22,0)),"") -> 9903 · Stratejik Hamle Programı | C16: Makine desteği (faiz ile birlikte olmaz) | D16: %25 | E16: SYT %15 ve ≈ 226 mn TL | F16: — | G16: — | H16: 9903 m.16/2-b, m.16/3 | I16: Mevzuat + Hesaplanan | J16: K02
... A53: P17 | B53: =IFERROR(INDEX(Programlar!$B$5:$B$22,MATCH(A53,Programlar!$A$5:$A$22,0)),"") -> YEKA 2026 (GES-2026, RES-2026 yarışmaları) | C53: Saha ve bağlantı kapasitesi kullanım hakkı | D53: — | E53: — | F53: 49 yıl | G53: — | H53: Şartname m.1 | I53: Mevzuat | J53: K21, K22

Sheet Uygunluk Kuralları
A1: Makine tarafından kontrol edilebilir uygunluk kuralları
A2: Sonuç: Şart (sağlanmazsa uygun değil) · Engel (varsa uygun değil) · Uyarı · Bilgi. Alan adları karar motorundaki değişkenlere karşılık gelir.
A4: Kural ID | B4: Program(lar) | C4: Alan | D4: Operatör | E4: Değer | F4: Birim | G4: Sonuç | H4: Açıklama | I4: Dayanak | J4: Etiket | K4: Kaynak
A5: R001 | B5: P01-P05 | C5: basvuru_tarihi | D5: ≤ | E5: 31.12.2030 | F5: tarih | G5: Şart | H5: Teşvik belgesi müracaatları 31.12.2030'a kadar değerlendirilir. | I5: 9903 m.5/5 | J5: Mevzuat | K5: K02
A6: R002 | B6: P01-P05 | C6: harcama_tarihi | D6: ≥ | E6: müracaat tarihi | F6: tarih | G6: Engel | H6: Müracaattan önceki harcamalar belgeye alınmaz. | I6: 9903 m.5/6 | J6: Mevzuat | K6: K02
A7: R003 | B7: P04,P05 | C7: sabit_yatirim | D7: ≥ | E7: 15.100.000 (1-2. bölge) / 7.500.000 (3-6. bölge) | F7: TL | G7: Şart | H7: Asgari sabit yatırım (ayrıca belirtilmedikçe). | I7: 9903 m.5/2 | J7: Mevzuat + Teyit edilecek | K7: K02, K04
A8: R004 | B8: P04,P05 | C8: yatirim_konusu | D8: ∈ | E8: EK-3 listesi ve şartları | F8: NACE | G8: Şart | H8: TYKH, Yeşil/Dijital Dönüşüm ve m.9/1-v için aranmaz. | I8: 9903 m.5/1 | J8: Mevzuat | K8: K01
A9: R005 | B9: P05 | C9: yatirim_konusu | D9: ∉ | E9: 35.11/35.12 doğalgaz veya ithal kömüre dayalı elektrik üretimi | F9: NACE | G9: Engel | H9: EK-3: doğalgaz/ithal kömür elektrik üretimi desteklenmez. | I9: 9903 EK-3 (35.11-35.12) | J9: Mevzuat | K9: K01
A10: R006 | B10: P04,P05 | C10: ges_kurulu_guc | D10: ≥ | E10: 240 | F10: kW | G10: Şart | H10: 240 kW altı (çatı dahil) GES ve modernizasyon niteliğindeki GES yatırımları desteklenmez. | I10: 9903 EK-3 (35.12) | J10: Mevzuat | K10: K01
A11: R007 | B11: P05 | C11: sarj_istasyonu | D11: = | E11: Tebliğ şartları | F11: — | G11: Şart | H11: Şarj istasyonları tebliğle belirlenecek şartları sağlarsa desteklenir. | I11: 9903 EK-3 (35.15.01) | J11: Mevzuat | K11: K01
A12: R008 | B12: P05 | C12: depolama | D12: = | E12: EK-3'te var (35.16) | F12: — | G12: Bilgi | H12: Depolama EK-3'te; ancak vergi indirimi ve faiz yok. | I12: 9903 EK-3, m.10/2-3 | J12: Mevzuat | K12: K01, K02
A13: R009 | B13: P05 | C13: imalat_konusu | D13: ∉ | E13: 23.5 çimento, 23.6, 23.7, 23.32, 23.12.03, 23.99.05 | F13: NACE | G13: Engel | H13: EK-3 dışı; bu sektörlerde 9903'e yol yalnız Yeşil Dönüşüm Programı. | I13: 9903 EK-3 (23) · m.5/1 | J13: Mevzuat + Yorum | K13: K01
A14: R010 | B14: P05 | C14: imalat_konusu | D14: ∈ | E14: 24.10 için yalnız 24.10.05, 24.10.08 (DRI/elektroliz), 24.10.12; 24.4; 24.5 | F14: NACE | G14: Şart | H14: Temel demir-çelikte EK-3 dar; verimlilik yatırımı için Yeşil Dönüşüm yolu. | I14: 9903 EK-3 (24) | J14: Mevzuat + Yorum | K14: K01
A15: R011 | B15: P05 | C15: pv_panel_uretimi | D15: = | E15: Ingot dilimleme veya öncesinden başlayan hücre ile entegre | F15: — | G15: Şart | H15: Panel üretimi hücre kapasitesini aşmamak kaydıyla. | I15: 9903 EK-3 (26) | J15: Mevzuat | K15: K01
... A17: R013 | B17: P04 | C17: oz_tuketim_ges_res_kurulu_guc | D17: ≤ | E17: Bağlantı anlaşmasındaki sözleşme gücü | F17: kW | G17: Şart | H17: Teşvik kapsamı sözleşme gücüyle sınırlı. | I17: 9903 m.9/1-e | J17: Mevzuat | K17: K02
A18: R014 | B18: P04 | C18: oz_tuketim_ges_res | D18: → | E18: Faiz desteği yok | F18: — | G18: Bilgi | I18: 9903 m.9/2 | J18: Mevzuat | K18: K02
A19: R015 | B19: P04 | C19: bolge | D19: = | E19: 6 ve enerji dağıtım/depolama/gaz dağıtımı veya (e,f,g) dışı elektrik üretimi | F19: — | G19: Bilgi | H19: 6. bölgede Öncelikli sayılır ama vergi indirimi ve faiz yok. | I19: 9903 m.9/3 | J19: Mevzuat | K19: K02
A20: R016 | B20: P04 | C20: lng_depolama | D20: ≥ | E20: 500 mn TL (2026 ≈ 627,5 mn) | F20: TL | G20: Şart | H20: LNG ve yer altı gaz depolama Öncelikli. | I20: 9903 m.9/1-ğ | J20: Mevzuat + Hesaplanan | K20: K02
A21: R017 | B21: P05 | C21: enerji_uretim_dagitim_depolama_gaz | D21: → | E21: Vergi indirimi ve faiz yok | F21: — | G21: Bilgi | H21: Yalnız gümrük, KDV ve bölgesel SGK. | I21: 9903 m.10/2-3 | J21: Mevzuat | K21: K02
A22: R018 | B22: P05 | C22: il | D22: ≠ | E22: İstanbul | F22: il | G22: Bilgi | H22: İstanbul'daki Hedef yatırımlara vergi indirimi yok. | I22: 9903 m.10/2 | J22: Mevzuat | K22: K02
A23: R019 | B23: P05 | C23: faiz_bolge | D23: ∈ | E23: 4, 5, 6 | F23: bölge | G23: Şart | H23: Hedef yatırımda faiz desteği yalnız 4-6. bölgede. | I23: 9903 m.10/3 | J23: Mevzuat | K23: K02
A24: R020 | B24: P03 | C24: sabit_yatirim | D24: ≥ | E24: 100 mn TL (yüksek tek.) / 200 mn TL (diğer); 2026: 125 / ≈ 251 mn | F24: TL | G24: Şart | H24: Stratejik Hamle asgari tutarı. | I24: 9903 m.8/2 | J24: Mevzuat + Teyit edilecek + Hesaplanan | K24: K02, K04
A25: R021 | B25: P03,P07 | C25: yesil_dijital_sabit_yatirim | D25: ≥ | E25: 62.700.000 | F25: TL | G25: Bilgi | H25: Değerlendirme süreci olmadan Stratejik Hamle'den desteklenebilir. | I25: 9903 m.8/8 | J25: Mevzuat + Teyit edilecek | K25: K02, K04
A26: R022 | B26: P01-P03 | C26: makine_birim_fiyat | D26: ≥ | E26: 2.500.000 | F26: TL | G26: Şart | H26: Makine desteği birim fiyat alt sınırı (2 mn TL'nin 2026 değeri). | I26: 9903 m.16/1 | J26: Mevzuat + Teyit edilecek | K26: K02, K04
A27: R023 | B27: P01-P03 | C27: makine_ve_faiz | D27: ≠ | E27: Birlikte | F27: — | G27: Engel | H27: Makine desteği alan yatırıma faiz desteği verilmez. | I27: 9903 m.15/9, m.16/3 | J27: Mevzuat | K27: K02
A28: R024 | B28: P02 | C28: yatirim_konusu | D28: ∈ | E28: İlin Yerel Yatırım Konuları Listesi | F28: — | G28: Şart | H28: Proje bazında komite değerlendirmesi. | I28: 9903 m.7/3; Tebliğ EK-1 | J28: Mevzuat | K28: K05
A29: R025 | B29: P01-P05 | C29: olcek_ve_vergi | D29: = | E29: KOBİ değil ve vergi indirimi var | F29: — | G29: Uyarı | H29: Ekosistem geliştirme planı: SYT'nin ≥ %2'si kadar harcama yükümlülüğü. | I29: 9903 m.5/9 | J29: Mevzuat | K29: K02
A30: R026 | B30: P01-P05 | C30: yap_islet_yid | D30: ∉ | E30: 4283 Yap-İşlet, 3996 YİD, rödovans | F30: — | G30: Engel | H30: Bu yatırımlar vergi indiriminden yararlanamaz. | I30: 9903 m.20/3 | J30: Mevzuat | K30: K02
A31: R027 | B31: P04 | C31: elektrik_uretimi | D31: → | E31: Yatırım yeri tahsis edilmez | F31: — | G31: Bilgi | I31: 9903 m.21/3 | J31: Mevzuat | K31: K02
A32: R028 | B32: P01-P05 | C32: finansal_kiralama | D32: ≥ | E32: 3.800.000 | F32: TL | G32: Şart | H32: Her finansal kiralama şirketi için asgari tutar. | I32: 9903 m.5/3 | J32: Mevzuat + Teyit edilecek | K32: K02, K04
A33: R029 | B33: P01-P05 | C33: maddi_olmayan_varlik | D33: ≤ | E33: %25 | F33: SYT | G33: Şart | H33: Dijital Dönüşüm hariç. | I33: 9903 m.5/8 | J33: Mevzuat | K33: K02
A34: R030 | B34: P01-P05 | C34: gumruk_muafiyeti | D34: ∉ | E34: EK-4 GTİP listesi | F34: GTİP | G34: Bilgi | H34: EK-4'teki makineler muafiyetsiz ithal edilip SYT'ye dahil edilebilir. | I34: 9903 m.13/2, EK-4 | J34: Mevzuat | K34: K01
A35: R031 | B35: P06 | C35: ilce | D35: ∈ | E35: 7028 EK-2 deprem ilçeleri | F35: — | G35: Bilgi | H35: 31.12.2026'ya kadar müracaatta 6. bölge destekleri; imalatta EK-3 şartı aranmaz. | I35: 9903 geçici m.3 | J35: Mevzuat | K35: K02, K08
A36: R032 | B36: P06 | C36: il_ve_konum | D36: ∈ | E36: Cazibe EK-1 illerinde OSB/endüstri bölgesi + imalat (NACE 10-32, 38.2) | F36: — | G36: Bilgi | H36: 31.12.2026'ya kadar müracaatta 6. bölge destekleri. | I36: 9903 geçici m.4 | J36: Mevzuat | K36: K02, K07
A37: R033 | B37: P06 | C37: konum | D37: ∈ | E37: OSB/endüstri bölgesi veya EK-5 ilçesi | F37: — | G37: Bilgi | H37: SGK desteği bir (ikisi birden: iki) alt bölgeden. | I37: 9903 m.22 | J37: Mevzuat | K37: K01, K02
A38: R034 | B38: P07 | C38: sektor | D38: = | E38: İmalat sanayii; Türkiye'de yerleşik sermaye şirketi | F38: — | G38: Şart | I38: YDDP Tebliği | J38: Mevzuat | K38: K06
A39: R035 | B39: P07 | C39: yol_haritasi_raporu | D39: = | E39: Bakanlık şablonu; başvurudan sonra ≤ 40 iş günü | F39: — | G39: Şart | H39: En az bir proje önerisi içermeli. | I39: YDDP Tebliği | J39: Mevzuat | K39: K06
A40: R036 | B40: P07 | C40: proje_hedefi | D40: = | E40: Birim üretim başına ölçülebilir iyileşme (enerji, sera gazı, su, atık vb.) | F40: — | G40: Şart | H40: Hedefe ulaşılamazsa Öncelikli niteliği kaybedilir. | I40: YDDP Tebliği | J40: Mevzuat | K40: K06
A41: R037 | B41: P07 | C41: yatirim_cinsi | D41: ≠ | E41: Komple yeni yatırım | F41: — | G41: Engel | H41: Mevcut tesise ilave dışındaki yeni yatırımlar desteklenmez. | I41: YDDP Tebliği | J41: Mevzuat | K41: K06
A42: R038 | B42: P07 | C42: yek_uretim_tesisi | D42: → | E42: Ayrı teşvik belgesi | F42: — | G42: Bilgi | H42: YEK üretim tesisi bölgesel destekler için ayrı belgeyle. | I42: YDDP Tebliği | J42: Mevzuat | K42: K06
...

Sheet Yatırım Türü Matrisi
A1: Yatırım türü × program matrisi
A2: ✔ uygun · ◐ koşullu · ✖ kapsam dışı · — ilgisiz/değerlendirilmedi. Gerekçe ve madde için 'Matris Gerekçeleri' sayfasına bakın.
B3: Program ID → | C3: P04 | D3: P05 | E3: P03 | F3: P01 | G3: P02 | H3: P07 | I3: P08 | J3: P09 | K3: P10 | L3: P11 | M3: P13 | N3: P14 | O3: P15 | P3: P16 | Q3: P17
A4: ID | B4: Yatırım türü | C4: 9903 Öncelikli | D4: 9903 Hedef | E4: 9903 Stratejik | F4: 9903 THP | G4: 9903 YKH | H4: Yeşil Dönüşüm | I4: VAP | J4: EPS | K4: EKA | L4: KOSGEB YSDP | M4: TÜBİTAK 1832 | N4: HIT-30 | O4: YEKDEM | P4: Lisanssız | Q4: YEKA 2026
A5: T01 | B5: GES · öz tüketim (imalat) | C5: =IFERROR(INDEX('Matris Gerekçeleri'!$F$5:$F$84,MATCH($A5&"|"&C$3,'Matris Gerekçeleri'!$A$5:$A$84,0)),"—") -> ◐ | D5: =IFERROR(INDEX('Matris Gerekçeleri'!$F$5:$F$84,MATCH($A5&"|"&D$3,'Matris Gerekçeleri'!$A$5:$A$84,0)),"—") -> ✖ | E5: =IFERROR(INDEX('Matris Gerekçeleri'!$F$5:$F$84,MATCH($A5&"|"&E$3,'Matris Gerekçeleri'!$A$5:$A$84,0)),"—") -> — | F5: =IFERROR(INDEX('Matris Gerekçeleri'!$F$5:$F$84,MATCH($A5&"|"&F$3,'Matris Gerekçeleri'!$A$5:$A$84,0)),"—") -> — | G5: =IFERROR(INDEX('Matris Gerekçeleri'!$F$5:$F$84,MATCH($A5&"|"&G$3,'Matris Gerekçeleri'!$A$5:$A$84,0)),"—") -> — | H5: =IFERROR(INDEX('Matris Gerekçeleri'!$F$5:$F$84,MATCH($A5&"|"&H$3,'Matris Gerekçeleri'!$A$5:$A$84,0)),"—") -> ✖ | I5: =IFERROR(INDEX('Matris Gerekçeleri'!$F$5:$F$84,MATCH($A5&"|"&I$3,'Matris Gerekçeleri'!$A$5:$A$84,0)),"—") -> ✖ | J5: =IFERROR(INDEX('Matris Gerekçeleri'!$F$5:$F$84,MATCH($A5&"|"&J$3,'Matris Gerekçeleri'!$A$5:$A$84,0)),"—") -> ✖ | ... Q5: =IFERROR(INDEX('Matris Gerekçeleri'!$F$5:$F$84,MATCH($A5&"|"&Q$3,'Matris Gerekçeleri'!$A$5:$A$84,0)),"—") -> —
A6: T02 | B6: GES · öz tüketim (ticari/hizmet, diğer) | C6: =IFERROR(INDEX('Matris Gerekçeleri'!$F$5:$F$84,MATCH($A6&"|"&C$3,'Matris Gerekçeleri'!$A$5:$A$84,0)),"—") -> ✖ | D6: =IFERROR(INDEX('Matris Gerekçeleri'!$F$5:$F$84,MATCH($A6&"|"&D$3,'Matris Gerekçeleri'!$A$5:$A$84,0)),"—") -> ◐ | E6: =IFERROR(INDEX('Matris Gerekçeleri'!$F$5:$F$84,MATCH($A6&"|"&E$3,'Matris Gerekçeleri'!$A$5:$A$84,0)),"—") -> — | F6: =IFERROR(INDEX('Matris Gerekçeleri'!$F$5:$F$84,MATCH($A6&"|"&F$3,'Matris Gerekçeleri'!$A$5:$A$84,0)),"—") -> — | G6: =IFERROR(INDEX('Matris Gerekçeleri'!$F$5:$F$84,MATCH($A6&"|"&G$3,'Matris Gerekçeleri'!$A$5:$A$84,0)),"—") -> — | H6: =IFERROR(INDEX('Matris Gerekçeleri'!$F$5:$F$84,MATCH($A6&"|"&H$3,'Matris Gerekçeleri'!$A$5:$A$84,0)),"—") -> — | I6: =IFERROR(INDEX('Matris Gerekçeleri'!$F$5:$F$84,MATCH($A6&"|"&I$3,'Matris Gerekçeleri'!$A$5:$A$84,0)),"—") -> ✖ | J6: =IFERROR(INDEX('Matris Gerekçeleri'!$F$5:$F$84,MATCH($A6&"|"&J$3,'Matris Gerekçeleri'!$A$5:$A$84,0)),"—") -> — | ... Q6: =IFERROR(INDEX('Matris Gerekçeleri'!$F$5:$F$84,MATCH($A6&"|"&Q$3,'Matris Gerekçeleri'!$A$5:$A$84,0)),"—") -> —
A7: T03 | B7: GES · lisanslı / satış (YEKA dışı) | C7: =IFERROR(INDEX('Matris Gerekçeleri'!$F$5:$F$84,MATCH($A7&"|"&C$3,'Matris Gerekçeleri'!$A$5:$A$84,0)),"—") -> — | D7: =IFERROR(INDEX('Matris Gerekçeleri'!$F$5:$F$84,MATCH($A7&"|"&D$3,'Matris Gerekçeleri'!$A$5:$A$84,0)),"—") -> ◐ | E7: =IFERROR(INDEX('Matris Gerekçeleri'!$F$5:$F$84,MATCH($A7&"|"&E$3,'Matris Gerekçeleri'!$A$5:$A$84,0)),"—") -> — | F7: =IFERROR(INDEX('Matris Gerekçeleri'!$F$5:$F$84,MATCH($A7&"|"&F$3,'Matris Gerekçeleri'!$A$5:$A$84,0)),"—") -> — | G7: =IFERROR(INDEX('Matris Gerekçeleri'!$F$5:$F$84,MATCH($A7&"|"&G$3,'Matris Gerekçeleri'!$A$5:$A$84,0)),"—") -> — | H7: =IFERROR(INDEX('Matris Gerekçeleri'!$F$5:$F$84,MATCH($A7&"|"&H$3,'Matris Gerekçeleri'!$A$5:$A$84,0)),"—") -> — | I7: =IFERROR(INDEX('Matris Gerekçeleri'!$F$5:$F$84,MATCH($A7&"|"&I$3,'Matris Gerekçeleri'!$A$5:$A$84,0)),"—") -> — | J7: =IFERROR(INDEX('Matris Gerekçeleri'!$F$5:$F$84,MATCH($A7&"|"&J$3,'Matris Gerekçeleri'!$A$5:$A$84,0)),"—") -> — | ... Q7: =IFERROR(INDEX('Matris Gerekçeleri'!$F$5:$F$84,MATCH($A7&"|"&Q$3,'Matris Gerekçeleri'!$A$5:$A$84,0)),"—") -> —
A8: T04 | B8: GES · YEKA | C8: =IFERROR(INDEX('Matris Gerekçeleri'!$F$5:$F$84,MATCH($A8&"|"&C$3,'Matris Gerekçeleri'!$A$5:$A$84,0)),"—") -> — | D8: =IFERROR(INDEX('Matris Gerekçeleri'!$F$5:$F$84,MATCH($A8&"|"&D$3,'Matris Gerekçeleri'!$A$5:$A$84,0)),"—") -> ◐ | E8: =IFERROR(INDEX('Matris Gerekçeleri'!$F$5:$F$84,MATCH($A8&"|"&E$3,'Matris Gerekçeleri'!$A$5:$A$84,0)),"—") -> — | F8: =IFERROR(INDEX('Matris Gerekçeleri'!$F$5:$F$84,MATCH($A8&"|"&F$3,'Matris Gerekçeleri'!$A$5:$A$84,0)),"—") -> — | G8: =IFERROR(INDEX('Matris Gerekçeleri'!$F$5:$F$84,MATCH($A8&"|"&G$3,'Matris Gerekçeleri'!$A$5:$A$84,0)),"—") -> — | H8: =IFERROR(INDEX('Matris Gerekçeleri'!$F$5:$F$84,MATCH($A8&"|"&H$3,'Matris Gerekçeleri'!$A$5:$A$84,0)),"—") -> — | I8: =IFERROR(INDEX('Matris Gerekçeleri'!$F$5:$F$84,MATCH($A8&"|"&I$3,'Matris Gerekçeleri'!$A$5:$A$84,0)),"—") -> — | J8: =IFERROR(INDEX('Matris Gerekçeleri'!$F$5:$F$84,MATCH($A8&"|"&J$3,'Matris Gerekçeleri'!$A$5:$A$84,0)),"—") -> — | ... Q8: =IFERROR(INDEX('Matris Gerekçeleri'!$F$5:$F$84,MATCH($A8&"|"&Q$3,'Matris Gerekçeleri'!$A$5:$A$84,0)),"—") -> ✔
A9: T05 | B9: RES · öz tüketim | C9: =IFERROR(INDEX('Matris Gerekçeleri'!$F$5:$F$84,MATCH($A9&"|"&C$3,'Matris Gerekçeleri'!$A$5:$A$84,0)),"—") -> ◐ | D9: =IFERROR(INDEX('Matris Gerekçeleri'!$F$5:$F$84,MATCH($A9&"|"&D$3,'Matris Gerekçeleri'!$A$5:$A$84,0)),"—") -> — | E9: =IFERROR(INDEX('Matris Gerekçeleri'!$F$5:$F$84,MATCH($A9&"|"&E$3,'Matris Gerekçeleri'!$A$5:$A$84,0)),"—") -> — | F9: =IFERROR(INDEX('Matris Gerekçeleri'!$F$5:$F$84,MATCH($A9&"|"&F$3,'Matris Gerekçeleri'!$A$5:$A$84,0)),"—") -> — | G9: =IFERROR(INDEX('Matris Gerekçeleri'!$F$5:$F$84,MATCH($A9&"|"&G$3,'Matris Gerekçeleri'!$A$5:$A$84,0)),"—") -> — | H9: =IFERROR(INDEX('Matris Gerekçeleri'!$F$5:$F$84,MATCH($A9&"|"&H$3,'Matris Gerekçeleri'!$A$5:$A$84,0)),"—") -> — | I9: =IFERROR(INDEX('Matris Gerekçeleri'!$F$5:$F$84,MATCH($A9&"|"&I$3,'Matris Gerekçeleri'!$A$5:$A$84,0)),"—") -> — | J9: =IFERROR(INDEX('Matris Gerekçeleri'!$F$5:$F$84,MATCH($A9&"|"&J$3,'Matris Gerekçeleri'!$A$5:$A$84,0)),"—") -> — | ... Q9: =IFERROR(INDEX('Matris Gerekçeleri'!$F$5:$F$84,MATCH($A9&"|"&Q$3,'Matris Gerekçeleri'!$A$5:$A$84,0)),"—") -> —
A10: T06 | B10: RES · lisanslı / YEKA | C10: =IFERROR(INDEX('Matris Gerekçeleri'!$F$5:$F$84,MATCH($A10&"|"&C$3,'Matris Gerekçeleri'!$A$5:$A$84,0)),"—") -> — | D10: =IFERROR(INDEX('Matris Gerekçeleri'!$F$5:$F$84,MATCH($A10&"|"&D$3,'Matris Gerekçeleri'!$A$5:$A$84,0)),"—") -> ◐ | E10: =IFERROR(INDEX('Matris Gerekçeleri'!$F$5:$F$84,MATCH($A10&"|"&E$3,'Matris Gerekçeleri'!$A$5:$A$84,0)),"—") -> — | F10: =IFERROR(INDEX('Matris Gerekçeleri'!$F$5:$F$84,MATCH($A10&"|"&F$3,'Matris Gerekçeleri'!$A$5:$A$84,0)),"—") -> — | G10: =IFERROR(INDEX('Matris Gerekçeleri'!$F$5:$F$84,MATCH($A10&"|"&G$3,'Matris Gerekçeleri'!$A$5:$A$84,0)),"—") -> — | H10: =IFERROR(INDEX('Matris Gerekçeleri'!$F$5:$F$84,MATCH($A10&"|"&H$3,'Matris Gerekçeleri'!$A$5:$A$84,0)),"—") -> — | I10: =IFERROR(INDEX('Matris Gerekçeleri'!$F$5:$F$84,MATCH($A10&"|"&I$3,'Matris Gerekçeleri'!$A$5:$A$84,0)),"—") -> — | J10: =IFERROR(INDEX('Matris Gerekçeleri'!$F$5:$F$84,MATCH($A10&"|"&J$3,'Matris Gerekçeleri'!$A$5:$A$84,0)),"—") -> — | ... Q10: =IFERROR(INDEX('Matris Gerekçeleri'!$F$5:$F$84,MATCH($A10&"|"&Q$3,'Matris Gerekçeleri'!$A$5:$A$84,0)),"—") -> ✔
A11: T07 | B11: BESS · tüketim tesisine bütünleşik | C11: =IFERROR(INDEX('Matris Gerekçeleri'!$F$5:$F$84,MATCH($A11&"|"&C$3,'Matris Gerekçeleri'!$A$5:$A$84,0)),"—") -> ◐ | D11: =IFERROR(INDEX('Matris Gerekçeleri'!$F$5:$F$84,MATCH($A11&"|"&D$3,'Matris Gerekçeleri'!$A$5:$A$84,0)),"—") -> — | E11: =IFERROR(INDEX('Matris Gerekçeleri'!$F$5:$F$84,MATCH($A11&"|"&E$3,'Matris Gerekçeleri'!$A$5:$A$84,0)),"—") -> — | F11: =IFERROR(INDEX('Matris Gerekçeleri'!$F$5:$F$84,MATCH($A11&"|"&F$3,'Matris Gerekçeleri'!$A$5:$A$84,0)),"—") -> — | G11: =IFERROR(INDEX('Matris Gerekçeleri'!$F$5:$F$84,MATCH($A11&"|"&G$3,'Matris Gerekçeleri'!$A$5:$A$84,0)),"—") -> — | H11: =IFERROR(INDEX('Matris Gerekçeleri'!$F$5:$F$84,MATCH($A11&"|"&H$3,'Matris Gerekçeleri'!$A$5:$A$84,0)),"—") -> — | I11: =IFERROR(INDEX('Matris Gerekçeleri'!$F$5:$F$84,MATCH($A11&"|"&I$3,'Matris Gerekçeleri'!$A$5:$A$84,0)),"—") -> ✖ | J11: =IFERROR(INDEX('Matris Gerekçeleri'!$F$5:$F$84,MATCH($A11&"|"&J$3,'Matris Gerekçeleri'!$A$5:$A$84,0)),"—") -> — | ... Q11: =IFERROR(INDEX('Matris Gerekçeleri'!$F$5:$F$84,MATCH($A11&"|"&Q$3,'Matris Gerekçeleri'!$A$5:$A$84,0)),"—") -> —
A12: T08 | B12: BESS · üretim tesisine bütünleşik | C12: =IFERROR(INDEX('Matris Gerekçeleri'!$F$5:$F$84,MATCH($A12&"|"&C$3,'Matris Gerekçeleri'!$A$5:$A$84,0)),"—") -> — | D12: =IFERROR(INDEX('Matris Gerekçeleri'!$F$5:$F$84,MATCH($A12&"|"&D$3,'Matris Gerekçeleri'!$A$5:$A$84,0)),"—") -> ◐ | E12: =IFERROR(INDEX('Matris Gerekçeleri'!$F$5:$F$84,MATCH($A12&"|"&E$3,'Matris Gerekçeleri'!$A$5:$A$84,0)),"—") -> — | F12: =IFERROR(INDEX('Matris Gerekçeleri'!$F$5:$F$84,MATCH($A12&"|"&F$3,'Matris Gerekçeleri'!$A$5:$A$84,0)),"—") -> — | G12: =IFERROR(INDEX('Matris Gerekçeleri'!$F$5:$F$84,MATCH($A12&"|"&G$3,'Matris Gerekçeleri'!$A$5:$A$84,0)),"—") -> — | H12: =IFERROR(INDEX('Matris Gerekçeleri'!$F$5:$F$84,MATCH($A12&"|"&H$3,'Matris Gerekçeleri'!$A$5:$A$84,0)),"—") -> — | I12: =IFERROR(INDEX('Matris Gerekçeleri'!$F$5:$F$84,MATCH($A12&"|"&I$3,'Matris Gerekçeleri'!$A$5:$A$84,0)),"—") -> — | J12: =IFERROR(INDEX('Matris Gerekçeleri'!$F$5:$F$84,MATCH($A12&"|"&J$3,'Matris Gerekçeleri'!$A$5:$A$84,0)),"—") -> — | ... Q12: =IFERROR(INDEX('Matris Gerekçeleri'!$F$5:$F$84,MATCH($A12&"|"&Q$3,'Matris Gerekçeleri'!$A$5:$A$84,0)),"—") -> —
A13: T09 | B13: BESS · müstakil depolama | C13: =IFERROR(INDEX('Matris Gerekçeleri'!$F$5:$F$84,MATCH($A13&"|"&C$3,'Matris Gerekçeleri'!$A$5:$A$84,0)),"—") -> — | D13: =IFERROR(INDEX('Matris Gerekçeleri'!$F$5:$F$84,MATCH($A13&"|"&D$3,'Matris Gerekçeleri'!$A$5:$A$84,0)),"—") -> ◐ | E13: =IFERROR(INDEX('Matris Gerekçeleri'!$F$5:$F$84,MATCH($A13&"|"&E$3,'Matris Gerekçeleri'!$A$5:$A$84,0)),"—") -> — | F13: =IFERROR(INDEX('Matris Gerekçeleri'!$F$5:$F$84,MATCH($A13&"|"&F$3,'Matris Gerekçeleri'!$A$5:$A$84,0)),"—") -> — | G13: =IFERROR(INDEX('Matris Gerekçeleri'!$F$5:$F$84,MATCH($A13&"|"&G$3,'Matris Gerekçeleri'!$A$5:$A$84,0)),"—") -> — | H13: =IFERROR(INDEX('Matris Gerekçeleri'!$F$5:$F$84,MATCH($A13&"|"&H$3,'Matris Gerekçeleri'!$A$5:$A$84,0)),"—") -> — | I13: =IFERROR(INDEX('Matris Gerekçeleri'!$F$5:$F$84,MATCH($A13&"|"&I$3,'Matris Gerekçeleri'!$A$5:$A$84,0)),"—") -> — | J13: =IFERROR(INDEX('Matris Gerekçeleri'!$F$5:$F$84,MATCH($A13&"|"&J$3,'Matris Gerekçeleri'!$A$5:$A$84,0)),"—") -> — | ... Q13: =IFERROR(INDEX('Matris Gerekçeleri'!$F$5:$F$84,MATCH($A13&"|"&Q$3,'Matris Gerekçeleri'!$A$5:$A$84,0)),"—") -> —
A14: T10 | B14: HES | C14: =IFERROR(INDEX('Matris Gerekçeleri'!$F$5:$F$84,MATCH($A14&"|"&C$3,'Matris Gerekçeleri'!$A$5:$A$84,0)),"—") -> — | D14: =IFERROR(INDEX('Matris Gerekçeleri'!$F$5:$F$84,MATCH($A14&"|"&D$3,'Matris Gerekçeleri'!$A$5:$A$84,0)),"—") -> ◐ | E14: =IFERROR(INDEX('Matris Gerekçeleri'!$F$5:$F$84,MATCH($A14&"|"&E$3,'Matris Gerekçeleri'!$A$5:$A$84,0)),"—") -> — | F14: =IFERROR(INDEX('Matris Gerekçeleri'!$F$5:$F$84,MATCH($A14&"|"&F$3,'Matris Gerekçeleri'!$A$5:$A$84,0)),"—") -> — | G14: =IFERROR(INDEX('Matris Gerekçeleri'!$F$5:$F$84,MATCH($A14&"|"&G$3,'Matris Gerekçeleri'!$A$5:$A$84,0)),"—") -> — | H14: =IFERROR(INDEX('Matris Gerekçeleri'!$F$5:$F$84,MATCH($A14&"|"&H$3,'Matris Gerekçeleri'!$A$5:$A$84,0)),"—") -> — | I14: =IFERROR(INDEX('Matris Gerekçeleri'!$F$5:$F$84,MATCH($A14&"|"&I$3,'Matris Gerekçeleri'!$A$5:$A$84,0)),"—") -> — | J14: =IFERROR(INDEX('Matris Gerekçeleri'!$F$5:$F$84,MATCH($A14&"|"&J$3,'Matris Gerekçeleri'!$A$5:$A$84,0)),"—") -> — | ... Q14: =IFERROR(INDEX('Matris Gerekçeleri'!$F$5:$F$84,MATCH($A14&"|"&Q$3,'Matris Gerekçeleri'!$A$5:$A$84,0)),"—") -> —
A15: T11 | B15: Biyokütle / biyogaz · elektrik | C15: =IFERROR(INDEX('Matris Gerekçeleri'!$F$5:$F$84,MATCH($A15&"|"&C$3,'Matris Gerekçeleri'!$A$5:$A$84,0)),"—") -> — | D15: =IFERROR(INDEX('Matris Gerekçeleri'!$F$5:$F$84,MATCH($A15&"|"&D$3,'Matris Gerekçeleri'!$A$5:$A$84,0)),"—") -> ◐ | E15: =IFERROR(INDEX('Matris Gerekçeleri'!$F$5:$F$84,MATCH($A15&"|"&E$3,'Matris Gerekçeleri'!$A$5:$A$84,0)),"—") -> — | F15: =IFERROR(INDEX('Matris Gerekçeleri'!$F$5:$F$84,MATCH($A15&"|"&F$3,'Matris Gerekçeleri'!$A$5:$A$84,0)),"—") -> — | G15: =IFERROR(INDEX('Matris Gerekçeleri'!$F$5:$F$84,MATCH($A15&"|"&G$3,'Matris Gerekçeleri'!$A$5:$A$84,0)),"—") -> — | H15: =IFERROR(INDEX('Matris Gerekçeleri'!$F$5:$F$84,MATCH($A15&"|"&H$3,'Matris Gerekçeleri'!$A$5:$A$84,0)),"—") -> — | I15: =IFERROR(INDEX('Matris Gerekçeleri'!$F$5:$F$84,MATCH($A15&"|"&I$3,'Matris Gerekçeleri'!$A$5:$A$84,0)),"—") -> — | J15: =IFERROR(INDEX('Matris Gerekçeleri'!$F$5:$F$84,MATCH($A15&"|"&J$3,'Matris Gerekçeleri'!$A$5:$A$84,0)),"—") -> — | ... Q15: =IFERROR(INDEX('Matris Gerekçeleri'!$F$5:$F$84,MATCH($A15&"|"&Q$3,'Matris Gerekçeleri'!$A$5:$A$84,0)),"—") -> —
A16: T12 | B16: Jeotermal · elektrik | C16: =IFERROR(INDEX('Matris Gerekçeleri'!$F$5:$F$84,MATCH($A16&"|"&C$3,'Matris Gerekçeleri'!$A$5:$A$84,0)),"—") -> — | D16: =IFERROR(INDEX('Matris Gerekçeleri'!$F$5:$F$84,MATCH($A16&"|"&D$3,'Matris Gerekçeleri'!$A$5:$A$84,0)),"—") -> ◐ | E16: =IFERROR(INDEX('Matris Gerekçeleri'!$F$5:$F$84,MATCH($A16&"|"&E$3,'Matris Gerekçeleri'!$A$5:$A$84,0)),"—") -> — | F16: =IFERROR(INDEX('Matris Gerekçeleri'!$F$5:$F$84,MATCH($A16&"|"&F$3,'Matris Gerekçeleri'!$A$5:$A$84,0)),"—") -> — | G16: =IFERROR(INDEX('Matris Gerekçeleri'!$F$5:$F$84,MATCH($A16&"|"&G$3,'Matris Gerekçeleri'!$A$5:$A$84,0)),"—") -> — | H16: =IFERROR(INDEX('Matris Gerekçeleri'!$F$5:$F$84,MATCH($A16&"|"&H$3,'Matris Gerekçeleri'!$A$5:$A$84,0)),"—") -> — | I16: =IFERROR(INDEX('Matris Gerekçeleri'!$F$5:$F$84,MATCH($A16&"|"&I$3,'Matris Gerekçeleri'!$A$5:$A$84,0)),"—") -> — | J16: =IFERROR(INDEX('Matris Gerekçeleri'!$F$5:$F$84,MATCH($A16&"|"&J$3,'Matris Gerekçeleri'!$A$5:$A$84,0)),"—") -> — | ... Q16: =IFERROR(INDEX('Matris Gerekçeleri'!$F$5:$F$84,MATCH($A16&"|"&Q$3,'Matris Gerekçeleri'!$A$5:$A$84,0)),"—") -> —
... A26: T22 | B26: Yatırımsız iyileştirme (operasyonel) | C26: =IFERROR(INDEX('Matris Gerekçeleri'!$F$5:$F$84,MATCH($A26&"|"&C$3,'Matris Gerekçeleri'!$A$5:$A$84,0)),"—") -> ✖ | D26: =IFERROR(INDEX('Matris Gerekçeleri'!$F$5:$F$84,MATCH($A26&"|"&D$3,'Matris Gerekçeleri'!$A$5:$A$84,0)),"—") -> — | E26: =IFERROR(INDEX('Matris Gerekçeleri'!$F$5:$F$84,MATCH($A26&"|"&E$3,'Matris Gerekçeleri'!$A$5:$A$84,0)),"—") -> — | F26: =IFERROR(INDEX('Matris Gerekçeleri'!$F$5:$F$84,MATCH($A26&"|"&F$3,'Matris Gerekçeleri'!$A$5:$A$84,0)),"—") -> — | G26: =IFERROR(INDEX('Matris Gerekçeleri'!$F$5:$F$84,MATCH($A26&"|"&G$3,'Matris Gerekçeleri'!$A$5:$A$84,0)),"—") -> — | H26: =IFERROR(INDEX('Matris Gerekçeleri'!$F$5:$F$84,MATCH($A26&"|"&H$3,'Matris Gerekçeleri'!$A$5:$A$84,0)),"—") -> — | I26: =IFERROR(INDEX('Matris Gerekçeleri'!$F$5:$F$84,MATCH($A26&"|"&I$3,'Matris Gerekçeleri'!$A$5:$A$84,0)),"—") -> ✖ | J26: =IFERROR(INDEX('Matris Gerekçeleri'!$F$5:$F$84,MATCH($A26&"|"&J$3,'Matris Gerekçeleri'!$A$5:$A$84,0)),"—") -> — | ... Q26: =IFERROR(INDEX('Matris Gerekçeleri'!$F$5:$F$84,MATCH($A26&"|"&Q$3,'Matris Gerekçeleri'!$A$5:$A$84,0)),"—") -> —
B28: Özet (formül)
B29: ✔ uygun tür sayısı | C29: =COUNTIF(C$5:C$26,"✔") -> 0 | D29: =COUNTIF(D$5:D$26,"✔") -> 0 | E29: =COUNTIF(E$5:E$26,"✔") -> 0 | F29: =COUNTIF(F$5:F$26,"✔") -> 0 | G29: =COUNTIF(G$5:G$26,"✔") -> 0 | H29: =COUNTIF(H$5:H$26,"✔") -> 4 | I29: =COUNTIF(I$5:I$26,"✔") -> 6 | J29: =COUNTIF(J$5:J$26,"✔") -> 4 | ... Q29: =COUNTIF(Q$5:Q$26,"✔") -> 2
B30: ◐ koşullu tür sayısı | C30: =COUNTIF(C$5:C$26,"◐") -> 4 | D30: =COUNTIF(D$5:D$26,"◐") -> 14 | E30: =COUNTIF(E$5:E$26,"◐") -> 0 | F30: =COUNTIF(F$5:F$26,"◐") -> 1 | G30: =COUNTIF(G$5:G$26,"◐") -> 3 | H30: =COUNTIF(H$5:H$26,"◐") -> 3 | I30: =COUNTIF(I$5:I$26,"◐") -> 0 | J30: =COUNTIF(J$5:J$26,"◐") -> 0 | ... Q30: =COUNTIF(Q$5:Q$26,"◐") -> 0
B31: ✖ kapsam dışı tür sayısı | C31: =COUNTIF(C$5:C$26,"✖") -> 2 | D31: =COUNTIF(D$5:D$26,"✖") -> 1 | E31: =COUNTIF(E$5:E$26,"✖") -> 0 | F31: =COUNTIF(F$5:F$26,"✖") -> 0 | G31: =COUNTIF(G$5:G$26,"✖") -> 0 | H31: =COUNTIF(H$5:H$26,"✖") -> 1 | I31: =COUNTIF(I$5:I$26,"✖") -> 5 | J31: =COUNTIF(J$5:J$26,"✖") -> 2 | ... Q31: =COUNTIF(Q$5:Q$26,"✖") -> 0

Sheet Matris Gerekçeleri
A1: Yatırım türü × program gerekçeleri
A2: Matris bu tablodan INDEX/MATCH ile beslenir. Durum: ✔ uygun · ◐ koşullu · ✖ kapsam dışı. Satır eklenirse matris kendiliğinden güncellenir.
A4: Anahtar | B4: Tür ID | C4: Yatırım türü | D4: Program ID | E4: Program | F4: Durum | G4: Gerekçe | H4: Dayanak | I4: Etiket
A5: =B5&"|"&D5 -> T01|P04 | B5: T01 | C5: GES · öz tüketim (imalat) | D5: P04 | E5: 9903 Öncelikli | F5: ◐ | G5: Yalnız imalat; sözleşme gücüne kadar; ≥ 240 kW; faiz yok. | H5: 9903 m.9/1-e, m.9/2, EK-3 35.12 | I5: Mevzuat
A6: =B6&"|"&D6 -> T01|P05 | B6: T01 | C6: GES · öz tüketim (imalat) | D6: P05 | E6: 9903 Hedef | F6: ✖ | G6: Öncelikli (e) kapsamında değerlendirilir. | H6: 9903 m.9/1-e | I6: Yorum
A7: =B7&"|"&D7 -> T01|P07 | B7: T01 | C7: GES · öz tüketim (imalat) | D7: P07 | E7: Yeşil Dönüşüm | F7: ✖ | G7: YEK üretim tesisi ayrı belgeyle desteklenir. | H7: YDDP Tebliği | I7: Mevzuat
A8: =B8&"|"&D8 -> T01|P08 | B8: T01 | C8: GES · öz tüketim (imalat) | D8: P08 | E8: VAP | F8: ✖ | G8: YEK elektrik üretimi kapsam dışı. | H8: VAP UE m.6/7-ğ | I8: Mevzuat
A9: =B9&"|"&D9 -> T01|P09 | B9: T01 | C9: GES · öz tüketim (imalat) | D9: P09 | E9: EPS | F9: ✖ | G9: YEK elektrik üretimi kapsam dışı. | H9: EPS UE m.6/3-g | I9: Mevzuat
A10: =B10&"|"&D10 -> T01|P10 | B10: T01 | C10: GES · öz tüketim (imalat) | D10: P10 | E10: EKA | F10: ◐ | G10: Tamamlayıcı: karbon/enerji yoğunluğunu düşürürse performans desteği. | H10: EKA UE m.1 | I10: Yorum
A11: =B11&"|"&D11 -> T01|P11 | B11: T01 | C11: GES · öz tüketim (imalat) | D11: P11 | E11: KOSGEB YSDP | F11: ◐ | G11: KOBİ ise GES bileşeni (14 mn TL, %60, geri ödemeli); çağrı teyit. | H11: KOSGEB YSDP | I11: Duyuru
A12: =B12&"|"&D12 -> T01|P16 | B12: T01 | C12: GES · öz tüketim (imalat) | D12: P16 | E12: Lisanssız | F12: ✔ | G12: (h) bendi: sözleşme gücünün 2 katına kadar; saatlik mahsuplaşma. | H12: LÜY m.5/1-h, m.26 | I12: Mevzuat
A13: =B13&"|"&D13 -> T02|P04 | B13: T02 | C13: GES · öz tüketim (ticari/hizmet, diğer) | D13: P04 | E13: 9903 Öncelikli | F13: ✖ | G13: Öncelikli (e) yalnız imalat sanayii için. | H13: 9903 m.9/1-e | I13: Mevzuat
A14: =B14&"|"&D14 -> T02|P05 | B14: T02 | C14: GES · öz tüketim (ticari/hizmet, diğer) | D14: P05 | E14: 9903 Hedef | F14: ◐ | G14: EK-3 35.12 (≥ 240 kW); vergi indirimi ve faiz yok. | H14: 9903 EK-3, m.10/2-3 | I14: Mevzuat
A15: =B15&"|"&D15 -> T02|P08 | B15: T02 | C15: GES · öz tüketim (ticari/hizmet, diğer) | D15: P08 | E15: VAP | F15: ✖ | G15: YEK elektrik üretimi kapsam dışı. | H15: VAP UE m.6/7-ğ | I15: Mevzuat
A16: =B16&"|"&D16 -> T02|P10 | B16: T02 | C16: GES · öz tüketim (ticari/hizmet, diğer) | D16: P10 | E16: EKA | F16: ◐ | G16: Otel, AVM, hastane, ofis için tamamlayıcı. | H16: EKA duyurusu | I16: Yorum
... A84: =B84&"|"&D84 -> T22|P04 | B84: T22 | C84: Yatırımsız iyileştirme (operasyonel) | D84: P04 | E84: 9903 Öncelikli | F84: ✖ | G84: Teşvik belgesi sabit yatırım gerektirir. | H84: 9903 m.5/2 | I84: Mevzuat

Sheet Bölgesel Kurallar
A1: Bölgeye göre değişen kurallar (9903)
A2: İl sayısı İller sayfasından, asgari tutar Parasal Eşikler 2026 sayfasından formülle gelir.
A4: Bölge | B4: İl sayısı | C4: Asgari sabit yatırım 2026 (TL) | D4: SGK işveren desteği süresi (yıl) | E4: SGK işveren desteği oranı | F4: Sigorta primi işçi hissesi | G4: Hedef yatırımda faiz | H4: Alt bölge etkisi (m.22) | I4: Not | J4: Dayanak
A5: 1 | B5: =COUNTIF(İller!$C$5:$C$85,A5) -> 8 | C5: =IF(A5<=2,'Parasal Eşikler 2026'!$G$7,'Parasal Eşikler 2026'!$G$8) -> 15100000 | D5: 0 | E5: — | F5: Hayır | G5: Hayır | H5: OSB/endüstri bölgesi veya EK-5 ilçesi: bir alt bölgenin SGK süresi; ikisi birden: iki alt bölge. 6. bölgede +2 yıl. | I5: SGK işveren hissesi desteği yok (TYKH'de 8 yıl). | J5: 9903 m.18, m.19, m.22, m.10/3
A6: 2 | B6: =COUNTIF(İller!$C$5:$C$85,A6) -> 13 | C6: =IF(A6<=2,'Parasal Eşikler 2026'!$G$7,'Parasal Eşikler 2026'!$G$8) -> 15100000 | D6: 1 | E6: %50 | F6: Hayır | G6: Hayır | H6: OSB/endüstri bölgesi veya EK-5 ilçesi: bir alt bölgenin SGK süresi; ikisi birden: iki alt bölge. 6. bölgede +2 yıl. | J6: 9903 m.18, m.19, m.22, m.10/3
A7: 3 | B7: =COUNTIF(İller!$C$5:$C$85,A7) -> 17 | C7: =IF(A7<=2,'Parasal Eşikler 2026'!$G$7,'Parasal Eşikler 2026'!$G$8) -> 7500000 | D7: 2 | E7: %50 | F7: Hayır | G7: Hayır | H7: OSB/endüstri bölgesi veya EK-5 ilçesi: bir alt bölgenin SGK süresi; ikisi birden: iki alt bölge. 6. bölgede +2 yıl. | J7: 9903 m.18, m.19, m.22, m.10/3
A8: 4 | B8: =COUNTIF(İller!$C$5:$C$85,A8) -> 11 | C8: =IF(A8<=2,'Parasal Eşikler 2026'!$G$7,'Parasal Eşikler 2026'!$G$8) -> 7500000 | D8: 4 | E8: %50 | F8: Hayır | G8: Evet | H8: OSB/endüstri bölgesi veya EK-5 ilçesi: bir alt bölgenin SGK süresi; ikisi birden: iki alt bölge. 6. bölgede +2 yıl. | J8: 9903 m.18, m.19, m.22, m.10/3
A9: 5 | B9: =COUNTIF(İller!$C$5:$C$85,A9) -> 15 | C9: =IF(A9<=2,'Parasal Eşikler 2026'!$G$7,'Parasal Eşikler 2026'!$G$8) -> 7500000 | D9: 8 | E9: %50 | F9: Hayır | G9: Evet | H9: OSB/endüstri bölgesi veya EK-5 ilçesi: bir alt bölgenin SGK süresi; ikisi birden: iki alt bölge. 6. bölgede +2 yıl. | J9: 9903 m.18, m.19, m.22, m.10/3
A10: 6 | B10: =COUNTIF(İller!$C$5:$C$85,A10) -> 17 | C10: =IF(A10<=2,'Parasal Eşikler 2026'!$G$7,'Parasal Eşikler 2026'!$G$8) -> 7500000 | D10: 12 | E10: %100 | F10: Evet (10 yıl) | G10: Evet | H10: OSB/EK-5: bölgedeki süreye +2 yıl. | I10: Müteharrik hariç 6. bölge yatırımları Öncelikli (m.9/1-ç). | J10: 9903 m.18, m.19, m.22, m.10/3
A12: TYKH | D12: 8 (6. bölge 12) | I12: THP, YKH ve Stratejik Hamle'de SGK desteği bölgeden bağımsız 8 yıl (m.18/3).

Sheet İller
A1: İl katmanı · 81 il
A2: Bölge: 9903 EK-2 (RG 30.05.2025). Asgari tutar, SGK süresi ve Hedef faizi formülle gelir. Ajans verisi ka.gov.tr; yerel konular RG 31.01.2026 EK-1.
A4: Plaka | B4: İl | C4: Bölge (EK-2) | D4: Asgari sabit yatırım 2026 (TL) | E4: SGK işveren süresi (yıl) | F4: Hedef yatırımda faiz | G4: İstanbul istisnası | H4: Cazibe EK-1 ili (geçici m.4, OSB imalat → 6. bölge, 31.12.2026) | I4: Deprem ilçeleri (geçici m.3 → 6. bölge, 31.12.2026) | J4: EK-5 alt bölge ilçeleri (SGK) | K4: Yerel yatırım konuları (YKH 2026) | L4: Enerji bağlantılı yerel konu | M4: Kalkınma ajansı | N4: Ajans ofisi / YDO | O4: Telefon | P4: E-posta | Q4: Web | R4: Enerjisa dağıtım bölgesi (LÜY m.37/10) | S4: Etiketler
A5: 1 | B5: Adana | C5: 3 | D5: =IF(C5<=2,'Parasal Eşikler 2026'!$G$7,'Parasal Eşikler 2026'!$G$8) -> 7500000 | E5: =IFERROR(INDEX('Bölgesel Kurallar'!$D$5:$D$10,MATCH(C5,'Bölgesel Kurallar'!$A$5:$A$10,0)),"") -> 2 | F5: =IFERROR(INDEX('Bölgesel Kurallar'!$G$5:$G$10,MATCH(C5,'Bölgesel Kurallar'!$A$5:$A$10,0)),"") -> Hayır | G5: =IF(B5="İstanbul","Hedef'te vergi indirimi yok; Öncelikli (c) ve (j) İstanbul hariç; madencilik desteklenmez","—") -> — | H5: — | I5: — | J5: Aladağ, Feke, İmamoğlu, Karaisalı, Karataş, Pozantı, Saimbeyli, Tufanbeyli, Yumurtalık | K5: 1) Nişasta tabanlı kimyasal türevler ve ileri katma değerli ürünler · 2) Su ürünleri üretimi ve/veya katma değerli işleme · 3) Tarımsal ürün/atıklardan katma değerli ürünler (pamuk hasat atığından biyokömür, kompost dahil) · 4) Temizlik kimyasalları ve yüzey aktif maddeler | L5: Tarımsal ürün/atıklardan katma değerli ürünler (pamuk hasat atığından biyokömür, kompost dahil) | M5: Çukurova Kalkınma Ajansı | N5: Adana Merkez Ofis | O5: +90 322 363 00 39 | P5: — | Q5: https://www.cka.gov.tr/ | R5: Toroslar EDAŞ | S5: Bölge, EK-5, Cazibe, deprem: Mevzuat · YKH: Mevzuat · Ajans: Duyuru · Enerjisa sütunu: Teyit edilecek · Enerji bağlantısı: Yorum
A6: 2 | B6: Adıyaman | C6: 6 | D6: =IF(C6<=2,'Parasal Eşikler 2026'!$G$7,'Parasal Eşikler 2026'!$G$8) -> 7500000 | E6: =IFERROR(INDEX('Bölgesel Kurallar'!$D$5:$D$10,MATCH(C6,'Bölgesel Kurallar'!$A$5:$A$10,0)),"") -> 12 | F6: =IFERROR(INDEX('Bölgesel Kurallar'!$G$5:$G$10,MATCH(C6,'Bölgesel Kurallar'!$A$5:$A$10,0)),"") -> Evet | G6: =IF(B6="İstanbul","Hedef'te vergi indirimi yok; Öncelikli (c) ve (j) İstanbul hariç; madencilik desteklenmez","—") -> — | H6: Evet | I6: Besni, Çelikhan, Gerger, Gölbaşı, Kahta, Merkez, Samsat, Sincik, Tut | J6: — | K6: 1) Asgari 300 büyükbaş entegre et/süt hayvancılığı · 2) Badem işleme ve katma değerli badem mamulleri · 3) Dört yıldız ve üzeri konaklama tesisi · 4) Su ürünleri üretimi ve/veya katma değerli işleme | L6: — | M6: İpek Yolu Kalkınma Ajansı | N6: Adıyaman Yatırım Destek Ofisi | O6: +90 416 213 14 44 | P6: — | Q6: https://www.ika.org.tr/ | R6: — | S6: Bölge, EK-5, Cazibe, deprem: Mevzuat · YKH: Mevzuat · Ajans: Duyuru · Enerjisa sütunu: Teyit edilecek · Enerji bağlantısı: Yorum
A7: 3 | B7: Afyonkarahisar | C7: 4 | D7: =IF(C7<=2,'Parasal Eşikler 2026'!$G$7,'Parasal Eşikler 2026'!$G$8) -> 7500000 | E7: =IFERROR(INDEX('Bölgesel Kurallar'!$D$5:$D$10,MATCH(C7,'Bölgesel Kurallar'!$A$5:$A$10,0)),"") -> 4 | F7: =IFERROR(INDEX('Bölgesel Kurallar'!$G$5:$G$10,MATCH(C7,'Bölgesel Kurallar'!$A$5:$A$10,0)),"") -> Evet | G7: =IF(B7="İstanbul","Hedef'te vergi indirimi yok; Öncelikli (c) ve (j) İstanbul hariç; madencilik desteklenmez","—") -> — | H7: — | I7: — | J7: Bayat, Çobanlar, Evciler, Hocalar, İhsaniye, Kızılören, Sinanpaşa | K7: 1) Asgari 300 baş manda yetiştiriciliği ve/veya manda ürünleri entegre tesis · 2) Jeotermal kaynaklar ile su ürünleri yetiştiriciliği · 3) Kesimhane artıklarından katma değerli ürün · 4) Mermer atıklarından yüksek katma değerli ürün | L7: Jeotermal kaynaklar ile su ürünleri yetiştiriciliği | M7: Zafer Kalkınma Ajansı | N7: Afyonkarahisar Yatırım Destek Ofisi | O7: — | P7: afyonkarahisarydo@zafer.gov.tr | Q7: https://zafer.gov.tr/ | R7: — | S7: Bölge, EK-5, Cazibe, deprem: Mevzuat · YKH: Mevzuat · Ajans: Duyuru · Enerjisa sütunu: Teyit edilecek · Enerji bağlantısı: Yorum
A8: 4 | B8: Ağrı | C8: 6 | D8: =IF(C8<=2,'Parasal Eşikler 2026'!$G$7,'Parasal Eşikler 2026'!$G$8) -> 7500000 | E8: =IFERROR(INDEX('Bölgesel Kurallar'!$D$5:$D$10,MATCH(C8,'Bölgesel Kurallar'!$A$5:$A$10,0)),"") -> 12 | F8: =IFERROR(INDEX('Bölgesel Kurallar'!$G$5:$G$10,MATCH(C8,'Bölgesel Kurallar'!$A$5:$A$10,0)),"") -> Evet | G8: =IF(B8="İstanbul","Hedef'te vergi indirimi yok; Öncelikli (c) ve (j) İstanbul hariç; madencilik desteklenmez","—") -> — | H8: Evet | I8: — | J8: — | K8: 1) Alternatif turizm yatırımları (termal konaklama vb.) · 2) Asgari 1.000 küçükbaş entegre et/süt hayvancılığı · 3) Asgari 15 dekar entegre jeotermal sera tesisi · 4) Asgari 300 büyükbaş entegre et/süt hayvancılığı | L8: Asgari 15 dekar entegre jeotermal sera tesisi | M8: Serhat Kalkınma Ajansı | N8: Ağrı Yatırım Destek Ofisi | O8: — | P8: agriyatirimdestekofisi@serka.gov.tr | Q8: https://www.serka.gov.tr/ | R8: — | S8: Bölge, EK-5, Cazibe, deprem: Mevzuat · YKH: Mevzuat · Ajans: Duyuru · Enerjisa sütunu: Teyit edilecek · Enerji bağlantısı: Yorum
A9: 5 | B9: Amasya | C9: 4 | D9: =IF(C9<=2,'Parasal Eşikler 2026'!$G$7,'Parasal Eşikler 2026'!$G$8) -> 7500000 | E9: =IFERROR(INDEX('Bölgesel Kurallar'!$D$5:$D$10,MATCH(C9,'Bölgesel Kurallar'!$A$5:$A$10,0)),"") -> 4 | F9: =IFERROR(INDEX('Bölgesel Kurallar'!$G$5:$G$10,MATCH(C9,'Bölgesel Kurallar'!$A$5:$A$10,0)),"") -> Evet | G9: =IF(B9="İstanbul","Hedef'te vergi indirimi yok; Öncelikli (c) ve (j) İstanbul hariç; madencilik desteklenmez","—") -> — | H9: — | I9: — | J9: Göynücek, Hamamözü | K9: 1) Asgari 20 dekar entegre jeotermal sera tesisi · 2) Asgari 500 büyükbaş entegre et/süt hayvancılığı · 3) İşlenmiş ve/veya dondurulmuş katma değerli et ürünleri · 4) Yaşlı bakım merkezi | L9: Asgari 20 dekar entegre jeotermal sera tesisi | M9: Orta Karadeniz Kalkınma Ajansı | N9: Amasya Yatırım Destek Ofisi | O9: +90 358 212 69 66 | P9: info@investamasya.com | Q9: https://www.oka.gov.tr/ | R9: — | S9: Bölge, EK-5, Cazibe, deprem: Mevzuat · YKH: Mevzuat · Ajans: Duyuru · Enerjisa sütunu: Teyit edilecek · Enerji bağlantısı: Yorum
A10: 6 | B10: Ankara | C10: 1 | D10: =IF(C10<=2,'Parasal Eşikler 2026'!$G$7,'Parasal Eşikler 2026'!$G$8) -> 15100000 | E10: =IFERROR(INDEX('Bölgesel Kurallar'!$D$5:$D$10,MATCH(C10,'Bölgesel Kurallar'!$A$5:$A$10,0)),"") -> 0 | F10: =IFERROR(INDEX('Bölgesel Kurallar'!$G$5:$G$10,MATCH(C10,'Bölgesel Kurallar'!$A$5:$A$10,0)),"") -> Hayır | G10: =IF(B10="İstanbul","Hedef'te vergi indirimi yok; Öncelikli (c) ve (j) İstanbul hariç; madencilik desteklenmez","—") -> — | H10: — | I10: — | J10: Bala, Çamlıdere, Evren, Güdül, Haymana, Kalecik | K10: 1) Asgari 1.000 baş entegre tiftik keçisi yetiştiriciliği ve ürünleri · 2) Kırsal ilçelerde alternatif turizm yatırımları · 3) Tıbbi cihaz üretimi · 4) Toz metalurjisi, toz metalden ürün ve makine üretimi | L10: — | M10: Ankara Kalkınma Ajansı | N10: Ankara Merkez Ofis | O10: +90 312 310 03 00 | P10: bilgi@ankaraka.org.tr | Q10: https://www.ankaraka.org.tr// | R10: Başkent EDAŞ | S10: Bölge, EK-5, Cazibe, deprem: Mevzuat · YKH: Mevzuat · Ajans: Duyuru · Enerjisa sütunu: Teyit edilecek · Enerji bağlantısı: Yorum
A11: 7 | B11: Antalya | C11: 1 | D11: =IF(C11<=2,'Parasal Eşikler 2026'!$G$7,'Parasal Eşikler 2026'!$G$8) -> 15100000 | E11: =IFERROR(INDEX('Bölgesel Kurallar'!$D$5:$D$10,MATCH(C11,'Bölgesel Kurallar'!$A$5:$A$10,0)),"") -> 0 | F11: =IFERROR(INDEX('Bölgesel Kurallar'!$G$5:$G$10,MATCH(C11,'Bölgesel Kurallar'!$A$5:$A$10,0)),"") -> Hayır | G11: =IF(B11="İstanbul","Hedef'te vergi indirimi yok; Öncelikli (c) ve (j) İstanbul hariç; madencilik desteklenmez","—") -> — | H11: — | I11: — | J11: Akseki, Gündoğmuş, İbradı | K11: 1) Tıbbi ve aromatik bitkilerden katma değerli ürün · 2) Örtüaltı ve dikey tarım yüksek teknolojili ürün ve aksamları (düşük karbonlu ısıtma dahil) · 3) Simgesel mimari ve nitelikli kültür endüstrileri · 4) Spor/sağlık turizmi yatırımları | L11: Örtüaltı ve dikey tarım yüksek teknolojili ürün ve aksamları (düşük karbonlu ısıtma dahil) | M11: Batı Akdeniz Kalkınma Ajansı | N11: Antalya Investment Support Office | O11: +90 242 332 37 37 | P11: antalyaydo@baka.gov.tr | Q11: https://www.baka.gov.tr/ | R11: — | S11: Bölge, EK-5, Cazibe, deprem: Mevzuat · YKH: Mevzuat · Ajans: Duyuru · Enerjisa sütunu: Teyit edilecek · Enerji bağlantısı: Yorum
A12: 8 | B12: Artvin | C12: 4 | D12: =IF(C12<=2,'Parasal Eşikler 2026'!$G$7,'Parasal Eşikler 2026'!$G$8) -> 7500000 | E12: =IFERROR(INDEX('Bölgesel Kurallar'!$D$5:$D$10,MATCH(C12,'Bölgesel Kurallar'!$A$5:$A$10,0)),"") -> 4 | F12: =IFERROR(INDEX('Bölgesel Kurallar'!$G$5:$G$10,MATCH(C12,'Bölgesel Kurallar'!$A$5:$A$10,0)),"") -> Evet | G12: =IF(B12="İstanbul","Hedef'te vergi indirimi yok; Öncelikli (c) ve (j) İstanbul hariç; madencilik desteklenmez","—") -> — | H12: — | I12: — | J12: — | K12: 1) Ağaç ve orman ürünlerinden katma değerli ürün · 2) Doğa temelli turizm yatırımları · 3) Su ürünleri üretimi ve/veya katma değerli işleme · 4) Tıbbi ve aromatik bitkilerden katma değerli ürün | L12: — | M12: Doğu Karadeniz Kalkınma Ajansı | N12: Artvin Yatırım Destek Ofisi | O12: +90 462 455 40 74 | P12: — | Q12: https://www.doka.org.tr/ | R12: — | S12: Bölge, EK-5, Cazibe, deprem: Mevzuat · YKH: Mevzuat · Ajans: Duyuru · Enerjisa sütunu: Teyit edilecek · Enerji bağlantısı: Yorum
A13: 9 | B13: Aydın | C13: 2 | D13: =IF(C13<=2,'Parasal Eşikler 2026'!$G$7,'Parasal Eşikler 2026'!$G$8) -> 15100000 | E13: =IFERROR(INDEX('Bölgesel Kurallar'!$D$5:$D$10,MATCH(C13,'Bölgesel Kurallar'!$A$5:$A$10,0)),"") -> 1 | F13: =IFERROR(INDEX('Bölgesel Kurallar'!$G$5:$G$10,MATCH(C13,'Bölgesel Kurallar'!$A$5:$A$10,0)),"") -> Hayır | G13: =IF(B13="İstanbul","Hedef'te vergi indirimi yok; Öncelikli (c) ve (j) İstanbul hariç; madencilik desteklenmez","—") -> — | H13: — | I13: — | J13: Bozdoğan, Buharkent, Germencik, Karacasu, Karpuzlu, Koçarlı, Köşk, Kuyucak, Sultanhisar, Yenipazar | K13: 1) Akıllı tarım teknolojileri, makine, ekipman ve aksamları · 2) Alternatif turizm yatırımları (termal konaklama vb.) · 3) Tarımsal ürünlerden katma değerli ürün · 4) Yüksek ekonomik değerli endüstriyel süt ürünleri | L13: — | M13: Güney Ege Kalkınma Ajansı | N13: Aydın Yatırım Destek Ofisi | O13: +90 256 211 0 216 | P13: aydin@geka.gov.tr | Q13: https://geka.gov.tr/ | R13: — | S13: Bölge, EK-5, Cazibe, deprem: Mevzuat · YKH: Mevzuat · Ajans: Duyuru · Enerjisa sütunu: Teyit edilecek · Enerji bağlantısı: Yorum
A14: 10 | B14: Balıkesir | C14: 2 | D14: =IF(C14<=2,'Parasal Eşikler 2026'!$G$7,'Parasal Eşikler 2026'!$G$8) -> 15100000 | E14: =IFERROR(INDEX('Bölgesel Kurallar'!$D$5:$D$10,MATCH(C14,'Bölgesel Kurallar'!$A$5:$A$10,0)),"") -> 1 | F14: =IFERROR(INDEX('Bölgesel Kurallar'!$G$5:$G$10,MATCH(C14,'Bölgesel Kurallar'!$A$5:$A$10,0)),"") -> Hayır | G14: =IF(B14="İstanbul","Hedef'te vergi indirimi yok; Öncelikli (c) ve (j) İstanbul hariç; madencilik desteklenmez","—") -> — | H14: — | I14: — | J14: Balya, Dursunbey, Havran, İvrindi, Kepsut, Manyas, Savaştepe, Sındırgı | K14: 1) Asgari 20 dekar entegre jeotermal sera tesisi · 2) Entegre kırmızı et işleme ve katma değerli ürün · 3) Termal turizm konseptli konaklama ve kongre merkezi · 4) Zeytinyağı lisanslı depo | L14: Asgari 20 dekar entegre jeotermal sera tesisi | M14: Güney Marmara Kalkınma Ajansı | N14: Balıkesir Merkez Ofis | O14: +90 266 246 10 00 | P14: — | Q14: https://www.gmka.gov.tr/ | R14: — | S14: Bölge, EK-5, Cazibe, deprem: Mevzuat · YKH: Mevzuat · Ajans: Duyuru · Enerjisa sütunu: Teyit edilecek · Enerji bağlantısı: Yorum
A15: 11 | B15: Bilecik | C15: 3 | D15: =IF(C15<=2,'Parasal Eşikler 2026'!$G$7,'Parasal Eşikler 2026'!$G$8) -> 7500000 | E15: =IFERROR(INDEX('Bölgesel Kurallar'!$D$5:$D$10,MATCH(C15,'Bölgesel Kurallar'!$A$5:$A$10,0)),"") -> 2 | F15: =IFERROR(INDEX('Bölgesel Kurallar'!$G$5:$G$10,MATCH(C15,'Bölgesel Kurallar'!$A$5:$A$10,0)),"") -> Hayır | G15: =IF(B15="İstanbul","Hedef'te vergi indirimi yok; Öncelikli (c) ve (j) İstanbul hariç; madencilik desteklenmez","—") -> — | H15: — | I15: — | J15: Gölpazarı, İnhisar, Pazaryeri, Yenipazar | K15: 1) Asgari 1.000 küçükbaş entegre et/süt hayvancılığı · 2) Mermer atıklarından yüksek katma değerli ürün · 3) Meyve/sebze ve atıklarından katma değerli ürün · 4) Teknik seramik ürünleri (ileri seramik, alümina, zirkonya, silisyum karbür) | L15: — | M15: Bursa Eskişehir Bilecik Kalkınma Ajansı | N15: Bilecik Yatırım Destek Ofisi | O15: — | P15: — | Q15: https://www.bebka.org.tr/ | R15: — | S15: Bölge, EK-5, Cazibe, deprem: Mevzuat · YKH: Mevzuat · Ajans: Duyuru · Enerjisa sütunu: Teyit edilecek · Enerji bağlantısı: Yorum
A16: 12 | B16: Bingöl | C16: 6 | D16: =IF(C16<=2,'Parasal Eşikler 2026'!$G$7,'Parasal Eşikler 2026'!$G$8) -> 7500000 | E16: =IFERROR(INDEX('Bölgesel Kurallar'!$D$5:$D$10,MATCH(C16,'Bölgesel Kurallar'!$A$5:$A$10,0)),"") -> 12 | F16: =IFERROR(INDEX('Bölgesel Kurallar'!$G$5:$G$10,MATCH(C16,'Bölgesel Kurallar'!$A$5:$A$10,0)),"") -> Evet | G16: =IF(B16="İstanbul","Hedef'te vergi indirimi yok; Öncelikli (c) ve (j) İstanbul hariç; madencilik desteklenmez","—") -> — | H16: Evet | I16: — | J16: — | K16: 1) Asgari 300 büyükbaş entegre et/süt hayvancılığı · 2) Dört yıldız ve üzeri termal konaklama tesisi · 3) Entegre bal ve arı ürünleri · 4) Su ürünleri üretimi ve/veya katma değerli işleme | L16: — | M16: Fırat Kalkınma Ajansı | N16: Bingöl Yatırım Destek Ofisi | O16: +90 426 213 57 55 | P16: bingolydo@fka.gov.tr | Q16: https://fka.gov.tr// | R16: — | S16: Bölge, EK-5, Cazibe, deprem: Mevzuat · YKH: Mevzuat · Ajans: Duyuru · Enerjisa sütunu: Teyit edilecek · Enerji bağlantısı: Yorum
